Workbook
Name legenda_geral: Geral!#REF!

Sheet Geral
A1: DATA | B1: ÓRGÃO | C1: MUNICÍPIO | D1: TERRITÓRIO | E1: PLEITO | F1: ATO | G1: VALOR | H1: SITUAÇÃO
A2: Dezembro | B2: SESAB | C2: ABAIRA | D2: =_xlfn.XLOOKUP(Tabela1[[#This Row],[MUNICÍPIO]],referencias!C:C,referencias!B:B,"não consta") -> não consta | E2: REFORMA DO HOSPITAL ODIN MELLO | F2: CONVÊNIO | G2: 1170045.9 | H2: Ato dezembro Publicado
A3: Dezembro | B3: SESAB | C3: ABAIRA | D3: =_xlfn.XLOOKUP(Tabela1[[#This Row],[MUNICÍPIO]],referencias!C:C,referencias!B:B,"não consta") -> não consta | E3: CUSTEIO PARA AQUISIÇÃO DE MEDICAMENTOS E INSUMOS DO HOSPITAL MUNICIPAL ODIN MELLO | F3: CONVÊNIO | G3: 300000 | H3: Ato dezembro Publicado
A4: Dezembro | B4: SESAB | C4: ABARÉ | D4: =_xlfn.XLOOKUP(Tabela1[[#This Row],[MUNICÍPIO]],referencias!C:C,referencias!B:B,"não consta") -> ITAPARICA | E4: CONSTRUÇÃO DE UBS | F4: CONVÊNIO | G4: 1870068.6 | H4: Ato dezembro Publicado
A5: Dezembro | B5: SEC | C5: ABARÉ | D5: =_xlfn.XLOOKUP(Tabela1[[#This Row],[MUNICÍPIO]],referencias!C:C,referencias!B:B,"não consta") -> ITAPARICA | E5: AQUISIÇÃO DE MOBILIÁRIOS E MATERIAIS DE INFORMÁTICA | F5: CONVÊNIO | G5: 298921.65 | H5: Ato dezembro Publicado
A6: Dezembro | B6: SEC | C6: ABARÉ | D6: =_xlfn.XLOOKUP(Tabela1[[#This Row],[MUNICÍPIO]],referencias!C:C,referencias!B:B,"não consta") -> ITAPARICA | E6: REFORMA DA QUADRA MUNICIPAL PROFESSOR WALTER AUGUSTO JONES | F6: CONVÊNIO | G6: 246003.93 | H6: Ato dezembro Publicado
A7: Dezembro | B7: SEINFRA | C7: ÁGUA FRIA | D7: =_xlfn.XLOOKUP(Tabela1[[#This Row],[MUNICÍPIO]],referencias!C:C,referencias!B:B,"não consta") -> PORTAL DO SERTÃO | E7: CONSTRUÇÃO DE NOVA PONTE SOBRE O RIO INHAMBUPE, RODOVIA BA-084, TRECHO: PATAÍBA (ÁGUA FRIA) - BIRITINGA, KM 30,5 | F7: LICITAÇÃO | G7: 4410000 | H7: Ato dezembro Publicado
A8: Dezembro | B8: SEC | C8: ALAGOINHAS | D8: =_xlfn.XLOOKUP(Tabela1[[#This Row],[MUNICÍPIO]],referencias!C:C,referencias!B:B,"não consta") -> LITORAL NORTE E AGRESTE BAIANO | E8: CONSTRUÇÃO DE UMA ESCOLA COM 12 SALAS, COM QUADRA | F8: CONVÊNIO | G8: 10925311 | H8: Ato dezembro Publicado
A9: Dezembro | B9: SEC | C9: ALAGOINHAS | D9: =_xlfn.XLOOKUP(Tabela1[[#This Row],[MUNICÍPIO]],referencias!C:C,referencias!B:B,"não consta") -> LITORAL NORTE E AGRESTE BAIANO | E9: CONSTRUÇÃO DE CRECHE NO BAIRRO SANTA TEREZINHA | F9: CONVÊNIO | G9: 6899406.8 | H9: Ato dezembro Publicado
A10: Dezembro | B10: SEC | C10: ALAGOINHAS | D10: =_xlfn.XLOOKUP(Tabela1[[#This Row],[MUNICÍPIO]],referencias!C:C,referencias!B:B,"não consta") -> LITORAL NORTE E AGRESTE BAIANO | E10: AQUISIÇÃO DE MOBILIÁRIO PARA CRECHES MUNICIPAIS | F10: CONVÊNIO | G10: 299303.66 | H10: Ato dezembro Publicado
A11: Dezembro | B11: SEC | C11: ALAGOINHAS | D11: =_xlfn.XLOOKUP(Tabela1[[#This Row],[MUNICÍPIO]],referencias!C:C,referencias!B:B,"não consta") -> LITORAL NORTE E AGRESTE BAIANO | E11: EQUIPAMENTOS E MOBILIÁRIOS ESCOLAR | F11: CONVÊNIO | G11: 289694.53 | H11: Ato dezembro Publicado
A12: Dezembro | B12: SESAB | C12: ALAGOINHAS | D12: =_xlfn.XLOOKUP(Tabela1[[#This Row],[MUNICÍPIO]],referencias!C:C,referencias!B:B,"não consta") -> LITORAL NORTE E AGRESTE BAIANO | E12: REFORMA DE UBS | F12: CONVÊNIO | G12: 196000 | H12: Ato dezembro Publicado
A13: Dezembro | B13: SEC | C13: AMÉLIA RODRIGUES | D13: =_xlfn.XLOOKUP(Tabela1[[#This Row],[MUNICÍPIO]],referencias!C:C,referencias!B:B,"não consta") -> PORTAL DO SERTÃO | E13: AQUISIÇÃO DE EQUIPAMENTOS E MOBILIÁRIO ESCOLAR | F13: CONVÊNIO | G13: 199345.19 | H13: Ato dezembro Publicado
... A74: Dezembro | B74: SESAB | C74: CASTRO ALVES | D74: =_xlfn.XLOOKUP(Tabela1[[#This Row],[MUNICÍPIO]],referencias!C:C,referencias!B:B,"não consta") -> RECÔNCAVO | E74: REPARO DO TELHADO DO HOSPITAL MUNICIPAL | F74: CONVÊNIO | G74: 488235.28 | H74: Ato dezembro Publicado
B75: CONDER | C75: ACAJUTIBA | D75: =_xlfn.XLOOKUP(Tabela1[[#This Row],[MUNICÍPIO]],referencias!C:C,referencias!B:B,"não consta") -> LITORAL NORTE E AGRESTE BAIANO | E75: PAVIMENTAÇÃO EM PARALELEPÍPEDO E CALÇADA DA RUA GÓES CALMON NA SEDE | F75: INAUGURADA | G75: 1643720.2 | H75: ATENDIDO
A76: Dezembro | B76: CAR | C76: CHORROCHO | D76: =_xlfn.XLOOKUP(Tabela1[[#This Row],[MUNICÍPIO]],referencias!C:C,referencias!B:B,"não consta") -> não consta | E76: REFORMA DO MERCADO MUNICIPAL EM BARRA TARRACHIL | F76: CONVÊNIO | G76: 2500009.4 | H76: Ato dezembro Publicado
A77: Dezembro | B77: EMBASA | C77: CONCEIÇÃO DO ALMEIDA | D77: =_xlfn.XLOOKUP(Tabela1[[#This Row],[MUNICÍPIO]],referencias!C:C,referencias!B:B,"não consta") -> RECÔNCAVO | E77: PROJETO DE DUPLICAÇÃO DA ADUTORA DE CRUZ DAS ALMAS (CAJÁ) ATÉ SAPEAÇU/CONCEIÇÃO DO ALMEIDA | F77: CONTRATO | G77: 7300000 | H77: Ato dezembro Publicado
A78: Dezembro | B78: EMBASA | C78: CONDEÚBA | D78: =_xlfn.XLOOKUP(Tabela1[[#This Row],[MUNICÍPIO]],referencias!C:C,referencias!B:B,"não consta") -> SUDOESTE BAIANO | E78: IMPLANTAÇÃO DE SAA (REDE DE DISTRIBUIÇÃO E LIGAÇÕES) PARA OS POVOADOS DE MANGARITO, MANDACARU E BOA VISTA | F78: CONTRATO | G78: 1873376.3 | H78: Ato dezembro Publicado
A79: Dezembro | B79: SEINFRA | C79: COTEGIPE | D79: =_xlfn.XLOOKUP(Tabela1[[#This Row],[MUNICÍPIO]],referencias!C:C,referencias!B:B,"não consta") -> BACIA DO RIO GRANDE | E79: CONSTRUÇÃO DE 02 PONTES NO TRECHO SOBRE O RIACHO DO VEREDA NA BA-449, DISTRITO DE JUPAGUÁ (KM 49 E KM 50). Vão 50 e 30m. Comunidade Aguapiranga. | F79: LICITAÇÃO | G79: 9231281.3 | H79: Ato dezembro Publicado
A80: Dezembro | B80: SEINFRA | C80: CRAVOLÂNDIA | D80: =_xlfn.XLOOKUP(Tabela1[[#This Row],[MUNICÍPIO]],referencias!C:C,referencias!B:B,"não consta") -> VALE DO JIQUIRIÇÁ | E80: PAVIMENTAÇÃO CBUQ BR-420 - CRAVOLÂNDIA | F80: LICITAÇÃO | G80: 9100000 | H80: Ato dezembro Publicado
A81: Dezembro | B81: SEC | C81: CRAVOLÂNDIA | D81: =_xlfn.XLOOKUP(Tabela1[[#This Row],[MUNICÍPIO]],referencias!C:C,referencias!B:B,"não consta") -> VALE DO JIQUIRIÇÁ | E81: CONSTRUÇÃO DE UMA CRECHE NA SEDE | F81: CONVÊNIO | G81: 5889380 | H81: Ato dezembro Publicado
A82: Dezembro | B82: SEINFRA | C82: CURAÇA | D82: =_xlfn.XLOOKUP(Tabela1[[#This Row],[MUNICÍPIO]],referencias!C:C,referencias!B:B,"não consta") -> SERTÃO DO SÃO FRANCISCO | E82: RESTAURAÇÃO E DUPLICAÇÃO DA PAVIMENTAÇÃO EM TSD E CICLOFAIXA, TRECHO: ENTROCAMENTO DA BA-120 - CURAÇÁ | F82: Licitação | G82: 7477866.4 | H82: Ato dezembro Publicado
A83: Dezembro | B83: CAR | C83: CURAÇA | D83: =_xlfn.XLOOKUP(Tabela1[[#This Row],[MUNICÍPIO]],referencias!C:C,referencias!B:B,"não consta") -> SERTÃO DO SÃO FRANCISCO | E83: REQUALIFICAÇÃO DO MERCADO | F83: CONVÊNIO | G83: 1875541.2 | H83: Ato dezembro Publicado
A84: Dezembro | B84: SEINFRA | C84: DIAS D'AVILA | D84: =_xlfn.XLOOKUP(Tabela1[[#This Row],[MUNICÍPIO]],referencias!C:C,referencias!B:B,"não consta") -> METROPOLITANO DE SALVADOR | E84: PAVIMENTAÇÃO EM CBUQ DO TRECHO: ENTROCAMENTO BA-512 - ACESSO BARRAGEM SANTA HELENA | F84: Licitação | G84: 7690000 | H84: Ato dezembro Publicado
A85: Dezembro | B85: SEC | C85: DIAS D'AVILA | D85: =_xlfn.XLOOKUP(Tabela1[[#This Row],[MUNICÍPIO]],referencias!C:C,referencias!B:B,"não consta") -> METROPOLITANO DE SALVADOR | E85: AQUISIÇÃO DE EQUIPAMENTOS E MOBILIÁRIO ESCOLAR | F85: CONVÊNIO | G85: 167386.6 | H85: Ato dezembro Publicado
A86: Dezembro | B86: SEC | C86: DIAS D'AVILA | D86: =_xlfn.XLOOKUP(Tabela1[[#This Row],[MUNICÍPIO]],referencias!C:C,referencias!B:B,"não consta") -> METROPOLITANO DE SALVADOR | E86: AQUISIÇÃO DE EQUIPAMENTOS E MOBILIÁRIO ESCOLAR | F86: CONVÊNIO | G86: 144286.74 | H86: Ato dezembro Publicado
A87: Dezembro | B87: CERB | C87: DOM BASILIO | D87: =_xlfn.XLOOKUP(Tabela1[[#This Row],[MUNICÍPIO]],referencias!C:C,referencias!B:B,"não consta") -> SERTÃO PRODUTIVO | E87: IMPLANTAÇÃO DO SIAA - SISTEMA INTEGRADO DE ABASTECIMENTO DE ÁGUA NAS LOCALIDADES DE: SANTA LUZIA, TABUÁ, MORRO DO ENGENHO, ITAPICURU, LAGOA DO MORRO, CAIÇARA DO PIO, LAGOA COMPRIDA, POÇA DO OSÓRIO, LARANJO, PEIXE, ITAPICURU II, FAZENDINHA, CAIÇARA DA BARR | F87: CONTRATO | G87: 9319252.1 | H87: Ato dezembro Publicado
... A94: Dezembro | B94: SESAB | C94: GONGOGI | D94: =_xlfn.XLOOKUP(Tabela1[[#This Row],[MUNICÍPIO]],referencias!C:C,referencias!B:B,"não consta") -> MÉDIO RIO DE CONTAS | E94: CONSTRUÇÃO DE UBS | F94: CONVÊNIO | G94: 1870068.6 | H94: Ato dezembro Publicado
A95: 46174 | B95: CONDER | C95: ACAJUTIBA | D95: =_xlfn.XLOOKUP(Tabela1[[#This Row],[MUNICÍPIO]],referencias!C:C,referencias!B:B,"não consta") -> LITORAL NORTE E AGRESTE BAIANO | E95: CONSTRUÇÃO DA PRAÇA LAGOA SECA | F95: CONVÊNIO | G95: 278055.3 | H95: Ato junho publicado
A96: Dezembro | B96: SEC | C96: HELIÓPOLIS | D96: =_xlfn.XLOOKUP(Tabela1[[#This Row],[MUNICÍPIO]],referencias!C:C,referencias!B:B,"não consta") -> SEMIÁRIDO NORDESTE II | E96: REFORMA E AMPLIAÇÃO DA ESCOLA DOM PEDRO PRIMEIRO | F96: CONVÊNIO | G96: 3484341.4 | H96: Ato dezembro Publicado
A97: 46174 | B97: CONDER | C97: ACAJUTIBA | D97: =_xlfn.XLOOKUP(Tabela1[[#This Row],[MUNICÍPIO]],referencias!C:C,referencias!B:B,"não consta") -> LITORAL NORTE E AGRESTE BAIANO | E97: CONSTUÇÃO DA PRAÇA CANATUBIÁ | F97: CONVÊNIO | G97: 326174.07 | H97: Ato junho publicado
A98: 46174 | B98: CONDER | C98: ACAJUTIBA | D98: =_xlfn.XLOOKUP(Tabela1[[#This Row],[MUNICÍPIO]],referencias!C:C,referencias!B:B,"não consta") -> LITORAL NORTE E AGRESTE BAIANO | E98: CONSTRUÇÃO DA PRAÇA TIJUCO | F98: CONVÊNIO | G98: 373148.63 | H98: Ato junho publicado
A99: Dezembro | B99: SEC | C99: IBIPEBA | D99: =_xlfn.XLOOKUP(Tabela1[[#This Row],[MUNICÍPIO]],referencias!C:C,referencias!B:B,"não consta") -> IRECÊ | E99: AQUISIÇÃO DE INSTRUMENTOS MUSICAIS (FANFARRA) | F99: CONVÊNIO | G99: 195949.12 | H99: Ato dezembro Publicado
A100: Dezembro | B100: SEC | C100: IBIPEBA | D100: =_xlfn.XLOOKUP(Tabela1[[#This Row],[MUNICÍPIO]],referencias!C:C,referencias!B:B,"não consta") -> IRECÊ | E100: AQUISIÇÃO DE EQUIPAMENTOS E MOBILIÁRIO ESCOLAR | F100: CONVÊNIO | G100: 110325.14 | H100: Ato dezembro Publicado
A101: Dezembro | B101: SEC | C101: IBIRATAIA | D101: =_xlfn.XLOOKUP(Tabela1[[#This Row],[MUNICÍPIO]],referencias!C:C,referencias!B:B,"não consta") -> MÉDIO RIO DE CONTAS | E101: AQUISIÇÃO DE EQUIPAMENTOS E MOBILIÁRIOS ESCOLAR (INFANTIS) | F101: CONVÊNIO | G101: 373699.56 | H101: Ato dezembro Publicado
A102: Dezembro | B102: SEC | C102: IBOTIRAMA | D102: =_xlfn.XLOOKUP(Tabela1[[#This Row],[MUNICÍPIO]],referencias!C:C,referencias!B:B,"não consta") -> VELHO CHICO | E102: CONSTRUÇÃO DE UMA ESCOLA COM 6 SALAS, COM QUADRA POLIESPORTIVA COBERTA, NO BAIRRO JARDIM IMPERIAL | F102: CONVÊNIO | G102: 5036196.8 | H102: Ato dezembro Publicado
A103: 46174 | B103: CONDER | C103: ACAJUTIBA | D103: =_xlfn.XLOOKUP(Tabela1[[#This Row],[MUNICÍPIO]],referencias!C:C,referencias!B:B,"não consta") -> LITORAL NORTE E AGRESTE BAIANO | E103: CONSTRUÇÃO DA PRAÇA GANCHO DO BADOGUE | F103: CONVÊNIO | G103: 362296.08 | H103: Ato junho publicado
A104: 46174 | B104: CONDER | C104: ACAJUTIBA | D104: =_xlfn.XLOOKUP(Tabela1[[#This Row],[MUNICÍPIO]],referencias!C:C,referencias!B:B,"não consta") -> LITORAL NORTE E AGRESTE BAIANO | E104: CONSTRUÇÃO DA PRAÇA CRUZEIRO | F104: CONVÊNIO | G104: 465548.44 | H104: Ato junho publicado
A105: Dezembro | B105: CAR | C105: ICHU | D105: =_xlfn.XLOOKUP(Tabela1[[#This Row],[MUNICÍPIO]],referencias!C:C,referencias!B:B,"não consta") -> SISAL | E105: Reconstrução do Mercado Municipal | F105: CONVÊNIO | G105: 2000138.1 | H105: Ato dezembro Publicado
A106: Dezembro | B106: SEC | C106: INHAMBUPE | D106: =_xlfn.XLOOKUP(Tabela1[[#This Row],[MUNICÍPIO]],referencias!C:C,referencias!B:B,"não consta") -> LITORAL NORTE E AGRESTE BAIANO | E106: AQUISIÇÃO DE EQUIPAMENTOS E MOBILIÁRIO PARA A CRECHE | F106: CONVÊNIO | G106: 419279.27 | H106: Ato dezembro Publicado
...

Sheet referencias
A1: re | B1: Território | C1: Municipio
A2: 385 | B2: CHAPADA DIAMANTINA | C2: Abaíra
A3: 188 | B3: ITAPARICA | C3: Abaré
A4: 259 | B4: LITORAL NORTE E AGRESTE BAIANO | C4: Acajutiba
A5: 247 | B5: SEMIÁRIDO NORDESTE II | C5: Adustina
A6: 241 | B6: PORTAL DO SERTÃO | C6: Água Fria
A7: 409 | B7: MÉDIO RIO DE CONTAS | C7: Aiquara
A8: 12 | B8: LITORAL NORTE E AGRESTE BAIANO | C8: Alagoinhas
A9: 121 | B9: EXTREMO SUL | C9: Alcobaca
A10: 405 | B10: LITORAL SUL | C10: Almadina
A11: 68 | B11: VALE DO JIQUIRIÇÁ | C11: Amargosa
A12: 133 | B12: PORTAL DO SERTÃO | C12: Amélia Rodrigues
A13: 233 | B13: IRECÊ | C13: América Dourada
... A418: 50 | B418: IRECÊ | C418: Xique-Xique
